<?xml version="1.0"?>
<robot name="my_robot" xmlns:xacro="http://ros.org/wiki/xacro">

  <!-- Define robot constants -->
  <xacro:property name="base_width" value="0.141"/>
  <xacro:property name="base_length" value="0.163"/>
  <xacro:property name="base_height" value="0.02"/>

  <xacro:property name="wheel_radius" value="0.035"/>
  <xacro:property name="wheel_width" value="0.008"/>
  <xacro:property name="wheel_ygap" value="0.004"/>
  <xacro:property name="wheel_zoff" value="0.0"/>
  <xacro:property name="wheel_xoff" value="0.0"/>

  <xacro:property name="caster_radius" value="0.0127"/>
  <xacro:property name="caster_xoff" value="0.065"/>
  <xacro:property name="caster_zoff" value="0.0223"/>

  <!-- Define intertial property macros  -->
  <xacro:macro name="box_inertia" params="m w h d">
    <inertial>
      <origin xyz="0 0 0" rpy="${pi/2} 0 ${pi/2}"/>
      <mass value="${m}"/>
      <inertia ixx="${(m/12) * (h*h + d*d)}" ixy="0.0" ixz="0.0" iyy="${(m/12) * (w*w + d*d)}" iyz="0.0" izz="${(m/12) * (w*w + h*h)}"/>
    </inertial>
  </xacro:macro>

  <xacro:macro name="cylinder_inertia" params="m r h">
    <inertial>
      <origin xyz="0 0 0" rpy="${pi/2} 0 0" />
      <mass value="${m}"/>
      <inertia ixx="${(m/12) * (3*r*r + h*h)}" ixy = "0" ixz = "0" iyy="${(m/12) * (3*r*r + h*h)}" iyz = "0" izz="${(m/2) * (r*r)}"/>
    </inertial>
  </xacro:macro>

  <xacro:macro name="sphere_inertia" params="m r">
    <inertial>
      <mass value="${m}"/>
      <inertia ixx="${(2/5) * m * (r*r)}" ixy="0.0" ixz="0.0" iyy="${(2/5) * m * (r*r)}" iyz="0.0" izz="${(2/5) * m * (r*r)}"/>
    </inertial>
  </xacro:macro>

  <!-- Robot Base -->
  <link name="base_link">
    <visual>
      <geometry>
        <box size="${base_length} ${base_width} ${base_height}"/>
      </geometry>
      <material name="Cyan">
        <color rgba="0 1.0 1.0 1.0"/>
      </material>
    </visual>
    
    <collision>
      <geometry>
        <box size="${base_length} ${base_width} ${base_height}"/>
      </geometry>
    </collision>

    <xacro:box_inertia m="15" w="${base_width}" d="${base_length}" h="${base_height}"/>
  </link>
    
  <!-- Robot Footprint -->
  <link name="base_footprint"/>

  <joint name="base_joint" type="fixed">
    <parent link="base_footprint"/>
    <child link="base_link"/>
    <origin xyz="0.0 0.0 ${(wheel_radius-wheel_zoff)}" rpy="0 0 0"/>
  </joint>

  <!-- Wheels -->
  <xacro:macro name="wheel" params="prefix x_reflect y_reflect">
    <link name="${prefix}_link">
      <visual>
        <origin xyz="0 0 0" rpy="${pi/2} 0 0"/>
        <geometry>
            <cylinder radius="${wheel_radius}" length="${wheel_width}"/>
        </geometry>
        <material name="Gray">
          <color rgba="0.5 0.5 0.5 1.0"/>
        </material>
      </visual>
      
      <collision>
        <origin xyz="0 0 0" rpy="${pi/2} 0 0"/>
        <geometry>
          <cylinder radius="${wheel_radius}" length="${wheel_width}"/>
        </geometry>
      </collision>

      <xacro:cylinder_inertia m="0.5" r="${wheel_radius}" h="${wheel_width}"/>
    </link>

    <joint name="${prefix}_joint" type="continuous">
      <parent link="base_link"/>
      <child link="${prefix}_link"/>
      <origin xyz="${x_reflect*wheel_xoff} ${y_reflect*(base_width/2+wheel_ygap)} ${wheel_zoff}" rpy="0 0 0"/>
      <axis xyz="0 1 0"/>
    </joint>
  </xacro:macro>

  <xacro:wheel prefix="drivewhl_l" x_reflect="-1" y_reflect="1" />
  <xacro:wheel prefix="drivewhl_r" x_reflect="-1" y_reflect="-1" />

  <!-- Caster Wheel -->
  <link name="front_caster">
    <visual>
      <geometry>
        <!-- <sphere radius="${(wheel_radius+wheel_zoff-(base_height/2))}"/> -->
        <sphere radius="${caster_radius}"/>
      </geometry>
      <material name="Cyan">
        <color rgba="0 1.0 1.0 1.0"/>
      </material>
    </visual>
    <collision>
      <origin xyz="0 0 0" rpy="0 0 0"/>
      <geometry>
        <!-- <sphere radius="${(wheel_radius+wheel_zoff-(base_height/2))}"/> -->
        <sphere radius="${caster_radius}"/>
      </geometry>
    </collision>

    <!-- <xacro:sphere_inertia m="0.5" r="${(wheel_radius+wheel_zoff-(base_height/2))}"/> -->
    <xacro:sphere_inertia m="0.5" r="${caster_radius}"/>
  </link>

  <joint name="caster_joint" type="fixed">
    <parent link="base_link"/>
    <child link="front_caster"/>
    <origin xyz="${caster_xoff} 0.0 ${-caster_zoff}" rpy="0 0 0"/>
  </joint>
  
  <!-- Lidar -->
  <link name="lidar_link">
    <inertial>
      <origin xyz="0 0 0" rpy="0 0 0"/>
      <mass value="0.125"/>
      <inertia ixx="0.001"  ixy="0"  ixz="0" iyy="0.001" iyz="0" izz="0.001" />
    </inertial>

    <collision>
      <origin xyz="0 0 0" rpy="0 0 0"/>
      <geometry>
         <cylinder radius="0.0175" length="0.035"/>
      </geometry>
    </collision>

    <visual>
      <origin xyz="0 0 0" rpy="0 0 0"/>
      <geometry>
         <cylinder radius="0.0175" length="0.035"/>
      </geometry>
    </visual>
  </link>
    
  <joint name="lidar_joint" type="fixed">
    <parent link="base_link"/>
    <child link="lidar_link"/>
    <origin xyz="0 0 0.165" rpy="0 0 0"/>
  </joint>
  
  <!-- Camera -->
  <link name="camera_link">
    <visual>
      <origin xyz="0 0 0" rpy="0 0 0"/>
      <geometry>
        <box size="0.015 0.130 0.022"/>
      </geometry>
    </visual>

    <collision>
      <origin xyz="0 0 0" rpy="0 0 0"/>
      <geometry>
        <box size="0.015 0.090 0.025"/>
      </geometry>
    </collision>

    <inertial>
      <origin xyz="0 0 0" rpy="0 0 0"/>
      <mass value="0.035"/>
      <inertia ixx="0.001"  ixy="0"  ixz="0" iyy="0.001" iyz="0" izz="0.001" />
    </inertial>
  </link>
  
  <joint name="camera_joint" type="fixed">
    <parent link="base_link"/>
    <child link="camera_link"/>
    <origin xyz="0.06 0 0.10" rpy="0 0 0"/>
  </joint>
  
  <link name="imu_link">
    <visual>
      <geometry>
        <box size="0.01 0.01 0.01"/>
      </geometry>
    </visual>
    
    <collision>
      <geometry>
        <box size="0.01 0.01 0.01"/>
      </geometry>
    </collision>
      
    <xacro:box_inertia m="0.01" w="0.01" d="0.01" h="0.01"/>
  </link>
    
  <joint name="imu_joint" type="fixed">
    <parent link="base_link"/>
    <child link="imu_link"/>
    <origin xyz="-0.05 0 0.13"/>
  </joint>
  
  <!-- Robot Body -->
  <link name="body_link">
    <visual>
      <geometry>
        <box size="${(0.06*2 - 0.015)} 0.072 ${0.165 - (base_height/2) - (0.035/2)}"/>
      </geometry>
      <material name="Cyan">
        <color rgba="0 1.0 1.0 1.0"/>
      </material>
    </visual>
    
    <collision>
      <geometry>
        <box size="${(0.06*2 - 0.015)} 0.072 ${0.165 - (base_height/2) - (0.035/2)}"/>
      </geometry>
    </collision>

    <xacro:box_inertia m="15" w="${base_width}" d="${base_length}" h="${base_height}"/>
  </link>
    
  <joint name="body_joint" type="fixed">
    <parent link="base_link"/>
    <child link="body_link"/>
    <origin xyz="0.0 0.0 ${(base_height/2) + (0.165 - (base_height/2) - (0.035/2))/2}" rpy="0 0 0"/>
  </joint>
    
</robot>
